Workbook

Sheet Instructions
A1: Interactive Product Development Dashboard — Instructions
A3: Overview
A4: This workbook provides an interactive overview of product development initiatives, including KPIs, timelines, budget performance, resource allocation, delivery comparisons, revenue impact, status waterfall, and risk heatmap.
A6: Sheets & Purpose
A7: • Executive Summary: Top-line KPIs and status overview, filter-responsive via Master Visible Flag.
A8: • Delivery: Scatter (Budget vs Schedule), Bubble (Priority vs Budget vs Delivery Status), Planned vs Actual Duration.
A9: • Budget: Initiative-level budget analysis and Product Line totals with charts.
A10: • Team: Resource allocation by team with table and distribution chart.
A11: • Revenue: Expected vs Actual revenue by initiative, ranking table, and Product Line totals.
A12: • Status Waterfall: Stacked horizontal breakdown of initiatives count by status per product line.
A13: • Risk Heatmap: Matrix of Budget variance (%) vs Schedule variance (days), color-coded counts.
A14: • Global Filters: Centralized dropdowns for Product Line, Status, Priority, Team, optional Start/End dates.
... A45: • If totals do not align, use Row/Column totals in Risk Heatmap and confirm numeric variances exist for visible rows.

Sheet Data
A1: Initiative ID | B1: Initiative Name | C1: Product Line | D1: Status | E1: Start Date | F1: Target Completion Date | G1: Actual Completion Date | H1: Assigned Team Size | I1: Budget Allocated | J1: Budget Spent | K1: Resource Utilization (%) | L1: Priority Level | M1: Expected Revenue Impact ($) | N1: Actual Revenue Impact ($) | O1: Progress % (heuristic) | P1: Assigned Team | Q1: Planned Duration (days) | R1: Actual Duration (days) | S1: Schedule Variance (days) | T1: Budget Variance ($) | U1: Budget Variance (%) | V1: On-time (Yes=1, No=0) | W1: Revenue Delta ($) | X1: Visible (Filter Flag) | AA1: Global Include | AB1: Master Visible Flag
A2: INIT0001 | B2: Analytics Suite - Feature 1 | C2: Analytics Suite | D2: Testing | E2: 44971 | F2: 45100 | H2: 8 | I2: 1000000 | J2: 617883 | K2: 77 | L2: Medium | M2: 5000000 | O2: 80 | P2: Team Alpha | Q2: 129 | T2: 382117 | U2: 38.2117 | V2: 0 | X2: 1 | AA2: =AND(OR('Global Filters'!$B$2="",EXACT(TRIM(C2),TRIM('Global Filters'!$B$2))),OR('Global Filters'!$B$3="",EXACT(TRIM(D2),TRIM('Global Filters'!$B$3))),OR('Global Filters'!$B$4="",EXACT(TRIM(L2),TRIM('Global Filters'!$B$4))),OR('Global Filters'!$B$5="",EXACT(TRIM(P2),TRIM('Global Filters'!$B$5))),OR('Global Filters'!$B$6="",E2>= 'Global Filters'!$B$6),OR('Global Filters'!$B$7="",F2<= 'Global Filters'!$B$7)) -> TRUE | AB2: =IF(AND(AA2,X2=1),1,0) -> 1
A3: INIT0002 | B3: Mobile App - Feature 2 | C3: Mobile App | D3: On Hold | E3: 45139 | F3: 45207 | H3: 12 | I3: 100000 | J3: 75327 | K3: 66 | L3: Low | M3: 100000 | O3: 25 | P3: Team Alpha | Q3: 68 | T3: 24673 | U3: 24.673 | V3: 0 | X3: 1 | AA3: =AND(OR('Global Filters'!$B$2="",EXACT(TRIM(C3),TRIM('Global Filters'!$B$2))),OR('Global Filters'!$B$3="",EXACT(TRIM(D3),TRIM('Global Filters'!$B$3))),OR('Global Filters'!$B$4="",EXACT(TRIM(L3),TRIM('Global Filters'!$B$4))),OR('Global Filters'!$B$5="",EXACT(TRIM(P3),TRIM('Global Filters'!$B$5))),OR('Global Filters'!$B$6="",E3>= 'Global Filters'!$B$6),OR('Global Filters'!$B$7="",F3<= 'Global Filters'!$B$7)) -> TRUE | AB3: =IF(AND(AA3,X3=1),1,0) -> 1
A4: INIT0003 | B4: Analytics Suite - Feature 3 | C4: Analytics Suite | D4: Planning | E4: 45103 | F4: 45238 | H4: 10 | I4: 250000 | J4: 151608 | K4: 96 | L4: Medium | M4: 5000000 | O4: 10 | P4: Team Epsilon | Q4: 135 | T4: 98392 | U4: 39.3568 | V4: 0 | X4: 1 | AA4: =AND(OR('Global Filters'!$B$2="",EXACT(TRIM(C4),TRIM('Global Filters'!$B$2))),OR('Global Filters'!$B$3="",EXACT(TRIM(D4),TRIM('Global Filters'!$B$3))),OR('Global Filters'!$B$4="",EXACT(TRIM(L4),TRIM('Global Filters'!$B$4))),OR('Global Filters'!$B$5="",EXACT(TRIM(P4),TRIM('Global Filters'!$B$5))),OR('Global Filters'!$B$6="",E4>= 'Global Filters'!$B$6),OR('Global Filters'!$B$7="",F4<= 'Global Filters'!$B$7)) -> TRUE | AB4: =IF(AND(AA4,X4=1),1,0) -> 1
A5: INIT0004 | B5: Mobile App - Feature 4 | C5: Mobile App | D5: In Development | E5: 45000 | F5: 45132 | H5: 8 | I5: 50000 | J5: 30831 | K5: 75 | L5: Medium | M5: 100000 | O5: 50 | P5: Team Delta | Q5: 132 | T5: 19169 | U5: 38.338 | V5: 0 | X5: 1 | AA5: =AND(OR('Global Filters'!$B$2="",EXACT(TRIM(C5),TRIM('Global Filters'!$B$2))),OR('Global Filters'!$B$3="",EXACT(TRIM(D5),TRIM('Global Filters'!$B$3))),OR('Global Filters'!$B$4="",EXACT(TRIM(L5),TRIM('Global Filters'!$B$4))),OR('Global Filters'!$B$5="",EXACT(TRIM(P5),TRIM('Global Filters'!$B$5))),OR('Global Filters'!$B$6="",E5>= 'Global Filters'!$B$6),OR('Global Filters'!$B$7="",F5<= 'Global Filters'!$B$7)) -> TRUE | AB5: =IF(AND(AA5,X5=1),1,0) -> 1
A6: INIT0005 | B6: Data Infrastructure - Feature 5 | C6: Data Infrastructure | D6: Testing | E6: 45099 | F6: 45206 | H6: 10 | I6: 250000 | J6: 131069 | K6: 66 | L6: Medium | M6: 500000 | O6: 80 | P6: Team Alpha | Q6: 107 | T6: 118931 | U6: 47.5724 | V6: 0 | X6: 1 | AA6: =AND(OR('Global Filters'!$B$2="",EXACT(TRIM(C6),TRIM('Global Filters'!$B$2))),OR('Global Filters'!$B$3="",EXACT(TRIM(D6),TRIM('Global Filters'!$B$3))),OR('Global Filters'!$B$4="",EXACT(TRIM(L6),TRIM('Global Filters'!$B$4))),OR('Global Filters'!$B$5="",EXACT(TRIM(P6),TRIM('Global Filters'!$B$5))),OR('Global Filters'!$B$6="",E6>= 'Global Filters'!$B$6),OR('Global Filters'!$B$7="",F6<= 'Global Filters'!$B$7)) -> TRUE | AB6: =IF(AND(AA6,X6=1),1,0) -> 1
A7: INIT0006 | B7: Web Platform - Feature 6 | C7: Web Platform | D7: Testing | E7: 45064 | F7: 45200 | H7: 6 | I7: 1000000 | J7: 816443 | K7: 88 | L7: Low | M7: 500000 | O7: 80 | P7: Team Gamma | Q7: 136 | T7: 183557 | U7: 18.3557 | V7: 0 | X7: 1 | AA7: =AND(OR('Global Filters'!$B$2="",EXACT(TRIM(C7),TRIM('Global Filters'!$B$2))),OR('Global Filters'!$B$3="",EXACT(TRIM(D7),TRIM('Global Filters'!$B$3))),OR('Global Filters'!$B$4="",EXACT(TRIM(L7),TRIM('Global Filters'!$B$4))),OR('Global Filters'!$B$5="",EXACT(TRIM(P7),TRIM('Global Filters'!$B$5))),OR('Global Filters'!$B$6="",E7>= 'Global Filters'!$B$6),OR('Global Filters'!$B$7="",F7<= 'Global Filters'!$B$7)) -> TRUE | AB7: =IF(AND(AA7,X7=1),1,0) -> 1
A8: INIT0007 | B8: Data Infrastructure - Feature 7 | C8: Data Infrastructure | D8: Launched | E8: 45190 | F8: 45260 | G8: 45263 | H8: 11 | I8: 500000 | J8: 204259 | K8: 96 | L8: Medium | M8: 100000 | N8: 62161 | O8: 100 | P8: Team Alpha | Q8: 70 | R8: 73 | S8: 3 | T8: 295741 | U8: 59.1482 | V8: 0 | W8: -37839 | X8: 1 | AA8: =AND(OR('Global Filters'!$B$2="",EXACT(TRIM(C8),TRIM('Global Filters'!$B$2))),OR('Global Filters'!$B$3="",EXACT(TRIM(D8),TRIM('Global Filters'!$B$3))),OR('Global Filters'!$B$4="",EXACT(TRIM(L8),TRIM('Global Filters'!$B$4))),OR('Global Filters'!$B$5="",EXACT(TRIM(P8),TRIM('Global Filters'!$B$5))),OR('Global Filters'!$B$6="",E8>= 'Global Filters'!$B$6),OR('Global Filters'!$B$7="",F8<= 'Global Filters'!$B$7)) -> TRUE | AB8: =IF(AND(AA8,X8=1),1,0) -> 1
A9: INIT0008 | B9: Web Platform - Feature 8 | C9: Web Platform | D9: Planning | E9: 45160 | F9: 45202 | H9: 7 | I9: 250000 | J9: 215926 | K9: 83 | L9: High | M9: 5000000 | O9: 10 | P9: Team Alpha | Q9: 42 | T9: 34074 | U9: 13.6296 | V9: 0 | X9: 1 | AA9: =AND(OR('Global Filters'!$B$2="",EXACT(TRIM(C9),TRIM('Global Filters'!$B$2))),OR('Global Filters'!$B$3="",EXACT(TRIM(D9),TRIM('Global Filters'!$B$3))),OR('Global Filters'!$B$4="",EXACT(TRIM(L9),TRIM('Global Filters'!$B$4))),OR('Global Filters'!$B$5="",EXACT(TRIM(P9),TRIM('Global Filters'!$B$5))),OR('Global Filters'!$B$6="",E9>= 'Global Filters'!$B$6),OR('Global Filters'!$B$7="",F9<= 'Global Filters'!$B$7)) -> TRUE | AB9: =IF(AND(AA9,X9=1),1,0) -> 1
A10: INIT0009 | B10: Analytics Suite - Feature 9 | C10: Analytics Suite | D10: Launched | E10: 45050 | F10: 45175 | G10: 45177 | H10: 10 | I10: 100000 | J10: 106841 | K10: 97 | L10: Critical | M10: 1000000 | N10: 740974 | O10: 100 | P10: Team Alpha | Q10: 125 | R10: 127 | S10: 2 | T10: -6841 | U10: -6.841 | V10: 0 | W10: -259026 | X10: 1 | AA10: =AND(OR('Global Filters'!$B$2="",EXACT(TRIM(C10),TRIM('Global Filters'!$B$2))),OR('Global Filters'!$B$3="",EXACT(TRIM(D10),TRIM('Global Filters'!$B$3))),OR('Global Filters'!$B$4="",EXACT(TRIM(L10),TRIM('Global Filters'!$B$4))),OR('Global Filters'!$B$5="",EXACT(TRIM(P10),TRIM('Global Filters'!$B$5))),OR('Global Filters'!$B$6="",E10>= 'Global Filters'!$B$6),OR('Global Filters'!$B$7="",F10<= 'Global Filters'!$B$7)) -> TRUE | AB10: =IF(AND(AA10,X10=1),1,0) -> 1
A11: INIT0010 | B11: API - Feature 10 | C11: API | D11: Planning | E11: 45124 | F11: 45166 | H11: 15 | I11: 100000 | J11: 98305 | K11: 73 | L11: Medium | M11: 500000 | O11: 10 | P11: Team Alpha | Q11: 42 | T11: 1695 | U11: 1.695 | V11: 0 | X11: 1 | AA11: =AND(OR('Global Filters'!$B$2="",EXACT(TRIM(C11),TRIM('Global Filters'!$B$2))),OR('Global Filters'!$B$3="",EXACT(TRIM(D11),TRIM('Global Filters'!$B$3))),OR('Global Filters'!$B$4="",EXACT(TRIM(L11),TRIM('Global Filters'!$B$4))),OR('Global Filters'!$B$5="",EXACT(TRIM(P11),TRIM('Global Filters'!$B$5))),OR('Global Filters'!$B$6="",E11>= 'Global Filters'!$B$6),OR('Global Filters'!$B$7="",F11<= 'Global Filters'!$B$7)) -> TRUE | AB11: =IF(AND(AA11,X11=1),1,0) -> 1
A12: INIT0011 | B12: Web Platform - Feature 11 | C12: Web Platform | D12: In Development | E12: 45189 | F12: 45224 | H12: 5 | I12: 50000 | J12: 33963 | K12: 71 | L12: Medium | M12: 100000 | O12: 50 | P12: Team Delta | Q12: 35 | T12: 16037 | U12: 32.074 | V12: 0 | X12: 1 | AA12: =AND(OR('Global Filters'!$B$2="",EXACT(TRIM(C12),TRIM('Global Filters'!$B$2))),OR('Global Filters'!$B$3="",EXACT(TRIM(D12),TRIM('Global Filters'!$B$3))),OR('Global Filters'!$B$4="",EXACT(TRIM(L12),TRIM('Global Filters'!$B$4))),OR('Global Filters'!$B$5="",EXACT(TRIM(P12),TRIM('Global Filters'!$B$5))),OR('Global Filters'!$B$6="",E12>= 'Global Filters'!$B$6),OR('Global Filters'!$B$7="",F12<= 'Global Filters'!$B$7)) -> TRUE | AB12: =IF(AND(AA12,X12=1),1,0) -> 1
A13: INIT0012 | B13: Web Platform - Feature 12 | C13: Web Platform | D13: Testing | E13: 45143 | F13: 45269 | H13: 6 | I13: 250000 | J13: 166799 | K13: 89 | L13: Medium | M13: 1000000 | O13: 80 | P13: Team Gamma | Q13: 126 | T13: 83201 | U13: 33.2804 | V13: 0 | X13: 1 | AA13: =AND(OR('Global Filters'!$B$2="",EXACT(TRIM(C13),TRIM('Global Filters'!$B$2))),OR('Global Filters'!$B$3="",EXACT(TRIM(D13),TRIM('Global Filters'!$B$3))),OR('Global Filters'!$B$4="",EXACT(TRIM(L13),TRIM('Global Filters'!$B$4))),OR('Global Filters'!$B$5="",EXACT(TRIM(P13),TRIM('Global Filters'!$B$5))),OR('Global Filters'!$B$6="",E13>= 'Global Filters'!$B$6),OR('Global Filters'!$B$7="",F13<= 'Global Filters'!$B$7)) -> TRUE | AB13: =IF(AND(AA13,X13=1),1,0) -> 1
A14: INIT0013 | B14: Analytics Suite - Feature 13 | C14: Analytics Suite | D14: On Hold | E14: 44979 | F14: 45010 | H14: 8 | I14: 1000000 | J14: 1099543 | K14: 95 | L14: Low | M14: 1000000 | O14: 25 | P14: Team Epsilon | Q14: 31 | T14: -99543 | U14: -9.9543 | V14: 0 | X14: 1 | AA14: =AND(OR('Global Filters'!$B$2="",EXACT(TRIM(C14),TRIM('Global Filters'!$B$2))),OR('Global Filters'!$B$3="",EXACT(TRIM(D14),TRIM('Global Filters'!$B$3))),OR('Global Filters'!$B$4="",EXACT(TRIM(L14),TRIM('Global Filters'!$B$4))),OR('Global Filters'!$B$5="",EXACT(TRIM(P14),TRIM('Global Filters'!$B$5))),OR('Global Filters'!$B$6="",E14>= 'Global Filters'!$B$6),OR('Global Filters'!$B$7="",F14<= 'Global Filters'!$B$7)) -> TRUE | AB14: =IF(AND(AA14,X14=1),1,0) -> 1
A15: INIT0014 | B15: API - Feature 14 | C15: API | D15: Planning | E15: 45099 | F15: 45199 | H15: 7 | I15: 250000 | J15: 247298 | K15: 79 | L15: Low | M15: 500000 | O15: 10 | P15: Team Alpha | Q15: 100 | T15: 2702 | U15: 1.0808 | V15: 0 | X15: 1 | AA15: =AND(OR('Global Filters'!$B$2="",EXACT(TRIM(C15),TRIM('Global Filters'!$B$2))),OR('Global Filters'!$B$3="",EXACT(TRIM(D15),TRIM('Global Filters'!$B$3))),OR('Global Filters'!$B$4="",EXACT(TRIM(L15),TRIM('Global Filters'!$B$4))),OR('Global Filters'!$B$5="",EXACT(TRIM(P15),TRIM('Global Filters'!$B$5))),OR('Global Filters'!$B$6="",E15>= 'Global Filters'!$B$6),OR('Global Filters'!$B$7="",F15<= 'Global Filters'!$B$7)) -> TRUE | AB15: =IF(AND(AA15,X15=1),1,0) -> 1
A16: INIT0015 | B16: Web Platform - Feature 15 | C16: Web Platform | D16: On Hold | E16: 45234 | F16: 45367 | H16: 14 | I16: 250000 | J16: 211151 | K16: 61 | L16: High | M16: 5000000 | O16: 25 | P16: Team Alpha | Q16: 133 | T16: 38849 | U16: 15.5396 | V16: 0 | X16: 1 | AA16: =AND(OR('Global Filters'!$B$2="",EXACT(TRIM(C16),TRIM('Global Filters'!$B$2))),OR('Global Filters'!$B$3="",EXACT(TRIM(D16),TRIM('Global Filters'!$B$3))),OR('Global Filters'!$B$4="",EXACT(TRIM(L16),TRIM('Global Filters'!$B$4))),OR('Global Filters'!$B$5="",EXACT(TRIM(P16),TRIM('Global Filters'!$B$5))),OR('Global Filters'!$B$6="",E16>= 'Global Filters'!$B$6),OR('Global Filters'!$B$7="",F16<= 'Global Filters'!$B$7)) -> TRUE | AB16: =IF(AND(AA16,X16=1),1,0) -> 1
A17: INIT0016 | B17: API - Feature 16 | C17: API | D17: Testing | E17: 45125 | F17: 45164 | H17: 12 | I17: 1000000 | J17: 866455 | K17: 72 | L17: Low | M17: 1000000 | O17: 80 | P17: Team Delta | Q17: 39 | T17: 133545 | U17: 13.3545 | V17: 0 | X17: 1 | AA17: =AND(OR('Global Filters'!$B$2="",EXACT(TRIM(C17),TRIM('Global Filters'!$B$2))),OR('Global Filters'!$B$3="",EXACT(TRIM(D17),TRIM('Global Filters'!$B$3))),OR('Global Filters'!$B$4="",EXACT(TRIM(L17),TRIM('Global Filters'!$B$4))),OR('Global Filters'!$B$5="",EXACT(TRIM(P17),TRIM('Global Filters'!$B$5))),OR('Global Filters'!$B$6="",E17>= 'Global Filters'!$B$6),OR('Global Filters'!$B$7="",F17<= 'Global Filters'!$B$7)) -> TRUE | AB17: =IF(AND(AA17,X17=1),1,0) -> 1
A18: INIT0017 | B18: Web Platform - Feature 17 | C18: Web Platform | D18: On Hold | E18: 45186 | F18: 45292 | H18: 11 | I18: 100000 | J18: 97251 | K18: 71 | L18: Low | M18: 1000000 | O18: 25 | P18: Team Gamma | Q18: 106 | T18: 2749 | U18: 2.749 | V18: 0 | X18: 1 | AA18: =AND(OR('Global Filters'!$B$2="",EXACT(TRIM(C18),TRIM('Global Filters'!$B$2))),OR('Global Filters'!$B$3="",EXACT(TRIM(D18),TRIM('Global Filters'!$B$3))),OR('Global Filters'!$B$4="",EXACT(TRIM(L18),TRIM('Global Filters'!$B$4))),OR('Global Filters'!$B$5="",EXACT(TRIM(P18),TRIM('Global Filters'!$B$5))),OR('Global Filters'!$B$6="",E18>= 'Global Filters'!$B$6),OR('Global Filters'!$B$7="",F18<= 'Global Filters'!$B$7)) -> TRUE | AB18: =IF(AND(AA18,X18=1),1,0) -> 1
A19: INIT0018 | B19: Mobile App - Feature 18 | C19: Mobile App | D19: Launched | E19: 45213 | F19: 45289 | G19: 45315 | H19: 6 | I19: 50000 | J19: 23890 | K19: 79 | L19: High | M19: 5000000 | N19: 5258316 | O19: 100 | P19: Team Gamma | Q19: 76 | R19: 102 | S19: 26 | T19: 26110 | U19: 52.22 | V19: 0 | W19: 258316 | X19: 1 | AA19: =AND(OR('Global Filters'!$B$2="",EXACT(TRIM(C19),TRIM('Global Filters'!$B$2))),OR('Global Filters'!$B$3="",EXACT(TRIM(D19),TRIM('Global Filters'!$B$3))),OR('Global Filters'!$B$4="",EXACT(TRIM(L19),TRIM('Global Filters'!$B$4))),OR('Global Filters'!$B$5="",EXACT(TRIM(P19),TRIM('Global Filters'!$B$5))),OR('Global Filters'!$B$6="",E19>= 'Global Filters'!$B$6),OR('Global Filters'!$B$7="",F19<= 'Global Filters'!$B$7)) -> TRUE | AB19: =IF(AND(AA19,X19=1),1,0) -> 1
A20: INIT0019 | B20: API - Feature 19 | C20: API | D20: Testing | E20: 45077 | F20: 45225 | H20: 13 | I20: 50000 | J20: 33821 | K20: 97 | L20: Medium | M20: 100000 | O20: 80 | P20: Team Epsilon | Q20: 148 | T20: 16179 | U20: 32.358 | V20: 0 | X20: 1 | AA20: =AND(OR('Global Filters'!$B$2="",EXACT(TRIM(C20),TRIM('Global Filters'!$B$2))),OR('Global Filters'!$B$3="",EXACT(TRIM(D20),TRIM('Global Filters'!$B$3))),OR('Global Filters'!$B$4="",EXACT(TRIM(L20),TRIM('Global Filters'!$B$4))),OR('Global Filters'!$B$5="",EXACT(TRIM(P20),TRIM('Global Filters'!$B$5))),OR('Global Filters'!$B$6="",E20>= 'Global Filters'!$B$6),OR('Global Filters'!$B$7="",F20<= 'Global Filters'!$B$7)) -> TRUE | AB20: =IF(AND(AA20,X20=1),1,0) -> 1
A21: INIT0020 | B21: Data Infrastructure - Feature 20 | C21: Data Infrastructure | D21: In Development | E21: 45198 | F21: 45304 | H21: 5 | I21: 500000 | J21: 171624 | K21: 68 | L21: Critical | M21: 500000 | O21: 50 | P21: Team Delta | Q21: 106 | T21: 328376 | U21: 65.6752 | V21: 0 | X21: 1 | AA21: =AND(OR('Global Filters'!$B$2="",EXACT(TRIM(C21),TRIM('Global Filters'!$B$2))),OR('Global Filters'!$B$3="",EXACT(TRIM(D21),TRIM('Global Filters'!$B$3))),OR('Global Filters'!$B$4="",EXACT(TRIM(L21),TRIM('Global Filters'!$B$4))),OR('Global Filters'!$B$5="",EXACT(TRIM(P21),TRIM('Global Filters'!$B$5))),OR('Global Filters'!$B$6="",E21>= 'Global Filters'!$B$6),OR('Global Filters'!$B$7="",F21<= 'Global Filters'!$B$7)) -> TRUE | AB21: =IF(AND(AA21,X21=1),1,0) -> 1
A22: INIT0021 | B22: API - Feature 21 | C22: API | D22: Launched | E22: 45088 | F22: 45164 | G22: 45200 | H22: 5 | I22: 250000 | J22: 201206 | K22: 80 | L22: Low | M22: 100000 | N22: 50329 | O22: 100 | P22: Team Beta | Q22: 76 | R22: 112 | S22: 36 | T22: 48794 | U22: 19.5176 | V22: 0 | W22: -49671 | X22: 1 | AA22: =AND(OR('Global Filters'!$B$2="",EXACT(TRIM(C22),TRIM('Global Filters'!$B$2))),OR('Global Filters'!$B$3="",EXACT(TRIM(D22),TRIM('Global Filters'!$B$3))),OR('Global Filters'!$B$4="",EXACT(TRIM(L22),TRIM('Global Filters'!$B$4))),OR('Global Filters'!$B$5="",EXACT(TRIM(P22),TRIM('Global Filters'!$B$5))),OR('Global Filters'!$B$6="",E22>= 'Global Filters'!$B$6),OR('Global Filters'!$B$7="",F22<= 'Global Filters'!$B$7)) -> TRUE | AB22: =IF(AND(AA22,X22=1),1,0) -> 1
A23: INIT0022 | B23: API - Feature 22 | C23: API | D23: In Development | E23: 45008 | F23: 45163 | H23: 9 | I23: 50000 | J23: 20176 | K23: 100 | L23: High | M23: 5000000 | O23: 50 | P23: Team Epsilon | Q23: 155 | T23: 29824 | U23: 59.648 | V23: 0 | X23: 1 | AA23: =AND(OR('Global Filters'!$B$2="",EXACT(TRIM(C23),TRIM('Global Filters'!$B$2))),OR('Global Filters'!$B$3="",EXACT(TRIM(D23),TRIM('Global Filters'!$B$3))),OR('Global Filters'!$B$4="",EXACT(TRIM(L23),TRIM('Global Filters'!$B$4))),OR('Global Filters'!$B$5="",EXACT(TRIM(P23),TRIM('Global Filters'!$B$5))),OR('Global Filters'!$B$6="",E23>= 'Global Filters'!$B$6),OR('Global Filters'!$B$7="",F23<= 'Global Filters'!$B$7)) -> TRUE | AB23: =IF(AND(AA23,X23=1),1,0) -> 1
A24: INIT0023 | B24: Data Infrastructure - Feature 23 | C24: Data Infrastructure | D24: Launched | E24: 44929 | F24: 44968 | G24: 44968 | H24: 15 | I24: 50000 | J24: 50680 | K24: 93 | L24: Low | M24: 500000 | N24: 256270 | O24: 100 | P24: Team Delta | Q24: 39 | R24: 39 | S24: 0 | T24: -680 | U24: -1.36 | V24: 1 | W24: -243730 | X24: 1 | AA24: =AND(OR('Global Filters'!$B$2="",EXACT(TRIM(C24),TRIM('Global Filters'!$B$2))),OR('Global Filters'!$B$3="",EXACT(TRIM(D24),TRIM('Global Filters'!$B$3))),OR('Global Filters'!$B$4="",EXACT(TRIM(L24),TRIM('Global Filters'!$B$4))),OR('Global Filters'!$B$5="",EXACT(TRIM(P24),TRIM('Global Filters'!$B$5))),OR('Global Filters'!$B$6="",E24>= 'Global Filters'!$B$6),OR('Global Filters'!$B$7="",F24<= 'Global Filters'!$B$7)) -> TRUE | AB24: =IF(AND(AA24,X24=1),1,0) -> 1
A25: INIT0024 | B25: Mobile App - Feature 24 | C25: Mobile App | D25: In Development | E25: 45086 | F25: 45149 | H25: 12 | I25: 50000 | J25: 30342 | K25: 79 | L25: High | M25: 500000 | O25: 50 | P25: Team Gamma | Q25: 63 | T25: 19658 | U25: 39.316 | V25: 0 | X25: 1 | AA25: =AND(OR('Global Filters'!$B$2="",EXACT(TRIM(C25),TRIM('Global Filters'!$B$2))),OR('Global Filters'!$B$3="",EXACT(TRIM(D25),TRIM('Global Filters'!$B$3))),OR('Global Filters'!$B$4="",EXACT(TRIM(L25),TRIM('Global Filters'!$B$4))),OR('Global Filters'!$B$5="",EXACT(TRIM(P25),TRIM('Global Filters'!$B$5))),OR('Global Filters'!$B$6="",E25>= 'Global Filters'!$B$6),OR('Global Filters'!$B$7="",F25<= 'Global Filters'!$B$7)) -> TRUE | AB25: =IF(AND(AA25,X25=1),1,0) -> 1
A26: INIT0025 | B26: Mobile App - Feature 25 | C26: Mobile App | D26: Planning | E26: 45160 | F26: 45323 | H26: 9 | I26: 1000000 | J26: 719294 | K26: 68 | L26: Medium | M26: 1000000 | O26: 10 | P26: Team Gamma | Q26: 163 | T26: 280706 | U26: 28.0706 | V26: 0 | X26: 1 | AA26: =AND(OR('Global Filters'!$B$2="",EXACT(TRIM(C26),TRIM('Global Filters'!$B$2))),OR('Global Filters'!$B$3="",EXACT(TRIM(D26),TRIM('Global Filters'!$B$3))),OR('Global Filters'!$B$4="",EXACT(TRIM(L26),TRIM('Global Filters'!$B$4))),OR('Global Filters'!$B$5="",EXACT(TRIM(P26),TRIM('Global Filters'!$B$5))),OR('Global Filters'!$B$6="",E26>= 'Global Filters'!$B$6),OR('Global Filters'!$B$7="",F26<= 'Global Filters'!$B$7)) -> TRUE | AB26: =IF(AND(AA26,X26=1),1,0) -> 1
A27: INIT0026 | B27: Data Infrastructure - Feature 26 | C27: Data Infrastructure | D27: Testing | E27: 45133 | F27: 45167 | H27: 5 | I27: 100000 | J27: 47945 | K27: 73 | L27: High | M27: 100000 | O27: 80 | P27: Team Beta | Q27: 34 | T27: 52055 | U27: 52.055 | V27: 0 | X27: 1 | AA27: =AND(OR('Global Filters'!$B$2="",EXACT(TRIM(C27),TRIM('Global Filters'!$B$2))),OR('Global Filters'!$B$3="",EXACT(TRIM(D27),TRIM('Global Filters'!$B$3))),OR('Global Filters'!$B$4="",EXACT(TRIM(L27),TRIM('Global Filters'!$B$4))),OR('Global Filters'!$B$5="",EXACT(TRIM(P27),TRIM('Global Filters'!$B$5))),OR('Global Filters'!$B$6="",E27>= 'Global Filters'!$B$6),OR('Global Filters'!$B$7="",F27<= 'Global Filters'!$B$7)) -> TRUE | AB27: =IF(AND(AA27,X27=1),1,0) -> 1
A28: INIT0027 | B28: Analytics Suite - Feature 27 | C28: Analytics Suite | D28: On Hold | E28: 45114 | F28: 45153 | H28: 7 | I28: 500000 | J28: 500617 | K28: 94 | L28: High | M28: 100000 | O28: 25 | P28: Team Alpha | Q28: 39 | T28: -617 | U28: -0.1234 | V28: 0 | X28: 1 | AA28: =AND(OR('Global Filters'!$B$2="",EXACT(TRIM(C28),TRIM('Global Filters'!$B$2))),OR('Global Filters'!$B$3="",EXACT(TRIM(D28),TRIM('Global Filters'!$B$3))),OR('Global Filters'!$B$4="",EXACT(TRIM(L28),TRIM('Global Filters'!$B$4))),OR('Global Filters'!$B$5="",EXACT(TRIM(P28),TRIM('Global Filters'!$B$5))),OR('Global Filters'!$B$6="",E28>= 'Global Filters'!$B$6),OR('Global Filters'!$B$7="",F28<= 'Global Filters'!$B$7)) -> TRUE | AB28: =IF(AND(AA28,X28=1),1,0) -> 1
A29: INIT0028 | B29: Analytics Suite - Feature 28 | C29: Analytics Suite | D29: Planning | E29: 44951 | F29: 45010 | H29: 4 | I29: 500000 | J29: 327725 | K29: 95 | L29: Critical | M29: 1000000 | O29: 10 | P29: Team Alpha | Q29: 59 | T29: 172275 | U29: 34.455 | V29: 0 | X29: 1 | AA29: =AND(OR('Global Filters'!$B$2="",EXACT(TRIM(C29),TRIM('Global Filters'!$B$2))),OR('Global Filters'!$B$3="",EXACT(TRIM(D29),TRIM('Global Filters'!$B$3))),OR('Global Filters'!$B$4="",EXACT(TRIM(L29),TRIM('Global Filters'!$B$4))),OR('Global Filters'!$B$5="",EXACT(TRIM(P29),TRIM('Global Filters'!$B$5))),OR('Global Filters'!$B$6="",E29>= 'Global Filters'!$B$6),OR('Global Filters'!$B$7="",F29<= 'Global Filters'!$B$7)) -> TRUE | AB29: =IF(AND(AA29,X29=1),1,0) -> 1
A30: INIT0029 | B30: Data Infrastructure - Feature 29 | C30: Data Infrastructure | D30: In Development | E30: 45081 | F30: 45218 | H30: 7 | I30: 50000 | J30: 41499 | K30: 99 | L30: High | M30: 500000 | O30: 50 | P30: Team Alpha | Q30: 137 | T30: 8501 | U30: 17.002 | V30: 0 | X30: 1 | AA30: =AND(OR('Global Filters'!$B$2="",EXACT(TRIM(C30),TRIM('Global Filters'!$B$2))),OR('Global Filters'!$B$3="",EXACT(TRIM(D30),TRIM('Global Filters'!$B$3))),OR('Global Filters'!$B$4="",EXACT(TRIM(L30),TRIM('Global Filters'!$B$4))),OR('Global Filters'!$B$5="",EXACT(TRIM(P30),TRIM('Global Filters'!$B$5))),OR('Global Filters'!$B$6="",E30>= 'Global Filters'!$B$6),OR('Global Filters'!$B$7="",F30<= 'Global Filters'!$B$7)) -> TRUE | AB30: =IF(AND(AA30,X30=1),1,0) -> 1
A31: INIT0030 | B31: Data Infrastructure - Feature 30 | C31: Data Infrastructure | D31: Planning | E31: 44985 | F31: 45042 | H31: 6 | I31: 500000 | J31: 229458 | K31: 76 | L31: Critical | M31: 500000 | O31: 10 | P31: Team Gamma | Q31: 57 | T31: 270542 | U31: 54.1084 | V31: 0 | X31: 1 | AA31: =AND(OR('Global Filters'!$B$2="",EXACT(TRIM(C31),TRIM('Global Filters'!$B$2))),OR('Global Filters'!$B$3="",EXACT(TRIM(D31),TRIM('Global Filters'!$B$3))),OR('Global Filters'!$B$4="",EXACT(TRIM(L31),TRIM('Global Filters'!$B$4))),OR('Global Filters'!$B$5="",EXACT(TRIM(P31),TRIM('Global Filters'!$B$5))),OR('Global Filters'!$B$6="",E31>= 'Global Filters'!$B$6),OR('Global Filters'!$B$7="",F31<= 'Global Filters'!$B$7)) -> TRUE | AB31: =IF(AND(AA31,X31=1),1,0) -> 1
A32: INIT0031 | B32: API - Feature 31 | C32: API | D32: Launched | E32: 44947 | F32: 45117 | G32: 45115 | H32: 3 | I32: 500000 | J32: 282241 | K32: 60 | L32: Medium | M32: 100000 | N32: 113481 | O32: 100 | P32: Team Beta | Q32: 170 | R32: 168 | S32: -2 | T32: 217759 | U32: 43.5518 | V32: 1 | W32: 13481 | X32: 1 | AA32: =AND(OR('Global Filters'!$B$2="",EXACT(TRIM(C32),TRIM('Global Filters'!$B$2))),OR('Global Filters'!$B$3="",EXACT(TRIM(D32),TRIM('Global Filters'!$B$3))),OR('Global Filters'!$B$4="",EXACT(TRIM(L32),TRIM('Global Filters'!$B$4))),OR('Global Filters'!$B$5="",EXACT(TRIM(P32),TRIM('Global Filters'!$B$5))),OR('Global Filters'!$B$6="",E32>= 'Global Filters'!$B$6),OR('Global Filters'!$B$7="",F32<= 'Global Filters'!$B$7)) -> TRUE | AB32: =IF(AND(AA32,X32=1),1,0) -> 1
A33: INIT0032 | B33: Analytics Suite - Feature 32 | C33: Analytics Suite | D33: Launched | E33: 45188 | F33: 45237 | G33: 45248 | H33: 10 | I33: 250000 | J33: 203867 | K33: 78 | L33: High | M33: 1000000 | N33: 824994 | O33: 100 | P33: Team Alpha | Q33: 49 | R33: 60 | S33: 11 | T33: 46133 | U33: 18.4532 | V33: 0 | W33: -175006 | X33: 1 | AA33: =AND(OR('Global Filters'!$B$2="",EXACT(TRIM(C33),TRIM('Global Filters'!$B$2))),OR('Global Filters'!$B$3="",EXACT(TRIM(D33),TRIM('Global Filters'!$B$3))),OR('Global Filters'!$B$4="",EXACT(TRIM(L33),TRIM('Global Filters'!$B$4))),OR('Global Filters'!$B$5="",EXACT(TRIM(P33),TRIM('Global Filters'!$B$5))),OR('Global Filters'!$B$6="",E33>= 'Global Filters'!$B$6),OR('Global Filters'!$B$7="",F33<= 'Global Filters'!$B$7)) -> TRUE | AB33: =IF(AND(AA33,X33=1),1,0) -> 1
A34: INIT0033 | B34: Mobile App - Feature 33 | C34: Mobile App | D34: In Development | E34: 45111 | F34: 45221 | H34: 4 | I34: 500000 | J34: 445416 | K34: 62 | L34: Critical | M34: 100000 | O34: 50 | P34: Team Gamma | Q34: 110 | T34: 54584 | U34: 10.9168 | V34: 0 | X34: 1 | AA34: =AND(OR('Global Filters'!$B$2="",EXACT(TRIM(C34),TRIM('Global Filters'!$B$2))),OR('Global Filters'!$B$3="",EXACT(TRIM(D34),TRIM('Global Filters'!$B$3))),OR('Global Filters'!$B$4="",EXACT(TRIM(L34),TRIM('Global Filters'!$B$4))),OR('Global Filters'!$B$5="",EXACT(TRIM(P34),TRIM('Global Filters'!$B$5))),OR('Global Filters'!$B$6="",E34>= 'Global Filters'!$B$6),OR('Global Filters'!$B$7="",F34<= 'Global Filters'!$B$7)) -> TRUE | AB34: =IF(AND(AA34,X34=1),1,0) -> 1
A35: INIT0034 | B35: Web Platform - Feature 34 | C35: Web Platform | D35: In Development | E35: 45151 | F35: 45249 | H35: 8 | I35: 50000 | J35: 29904 | K35: 71 | L35: Medium | M35: 100000 | O35: 50 | P35: Team Gamma | Q35: 98 | T35: 20096 | U35: 40.192 | V35: 0 | X35: 1 | AA35: =AND(OR('Global Filters'!$B$2="",EXACT(TRIM(C35),TRIM('Global Filters'!$B$2))),OR('Global Filters'!$B$3="",EXACT(TRIM(D35),TRIM('Global Filters'!$B$3))),OR('Global Filters'!$B$4="",EXACT(TRIM(L35),TRIM('Global Filters'!$B$4))),OR('Global Filters'!$B$5="",EXACT(TRIM(P35),TRIM('Global Filters'!$B$5))),OR('Global Filters'!$B$6="",E35>= 'Global Filters'!$B$6),OR('Global Filters'!$B$7="",F35<= 'Global Filters'!$B$7)) -> TRUE | AB35: =IF(AND(AA35,X35=1),1,0) -> 1
A36: INIT0035 | B36: Data Infrastructure - Feature 35 | C36: Data Infrastructure | D36: Launched | E36: 45124 | F36: 45276 | G36: 45322 | H36: 14 | I36: 100000 | J36: 39044 | K36: 63 | L36: Low | M36: 500000 | N36: 286299 | O36: 100 | P36: Team Gamma | Q36: 152 | R36: 198 | S36: 46 | T36: 60956 | U36: 60.956 | V36: 0 | W36: -213701 | X36: 1 | AA36: =AND(OR('Global Filters'!$B$2="",EXACT(TRIM(C36),TRIM('Global Filters'!$B$2))),OR('Global Filters'!$B$3="",EXACT(TRIM(D36),TRIM('Global Filters'!$B$3))),OR('Global Filters'!$B$4="",EXACT(TRIM(L36),TRIM('Global Filters'!$B$4))),OR('Global Filters'!$B$5="",EXACT(TRIM(P36),TRIM('Global Filters'!$B$5))),OR('Global Filters'!$B$6="",E36>= 'Global Filters'!$B$6),OR('Global Filters'!$B$7="",F36<= 'Global Filters'!$B$7)) -> TRUE | AB36: =IF(AND(AA36,X36=1),1,0) -> 1
A37: INIT0036 | B37: Analytics Suite - Feature 36 | C37: Analytics Suite | D37: Launched | E37: 45239 | F37: 45366 | G37: 45410 | H37: 14 | I37: 50000 | J37: 49503 | K37: 68 | L37: Low | M37: 5000000 | N37: 5721392 | O37: 100 | P37: Team Beta | Q37: 127 | R37: 171 | S37: 44 | T37: 497 | U37: 0.994 | V37: 0 | W37: 721392 | X37: 1 | AA37: =AND(OR('Global Filters'!$B$2="",EXACT(TRIM(C37),TRIM('Global Filters'!$B$2))),OR('Global Filters'!$B$3="",EXACT(TRIM(D37),TRIM('Global Filters'!$B$3))),OR('Global Filters'!$B$4="",EXACT(TRIM(L37),TRIM('Global Filters'!$B$4))),OR('Global Filters'!$B$5="",EXACT(TRIM(P37),TRIM('Global Filters'!$B$5))),OR('Global Filters'!$B$6="",E37>= 'Global Filters'!$B$6),OR('Global Filters'!$B$7="",F37<= 'Global Filters'!$B$7)) -> TRUE | AB37: =IF(AND(AA37,X37=1),1,0) -> 1
A38: INIT0037 | B38: Mobile App - Feature 37 | C38: Mobile App | D38: Launched | E38: 44959 | F38: 45055 | G38: 45050 | H38: 12 | I38: 1000000 | J38: 914022 | K38: 96 | L38: Low | M38: 500000 | N38: 592263 | O38: 100 | P38: Team Alpha | Q38: 96 | R38: 91 | S38: -5 | T38: 85978 | U38: 8.5978 | V38: 1 | W38: 92263 | X38: 1 | AA38: =AND(OR('Global Filters'!$B$2="",EXACT(TRIM(C38),TRIM('Global Filters'!$B$2))),OR('Global Filters'!$B$3="",EXACT(TRIM(D38),TRIM('Global Filters'!$B$3))),OR('Global Filters'!$B$4="",EXACT(TRIM(L38),TRIM('Global Filters'!$B$4))),OR('Global Filters'!$B$5="",EXACT(TRIM(P38),TRIM('Global Filters'!$B$5))),OR('Global Filters'!$B$6="",E38>= 'Global Filters'!$B$6),OR('Global Filters'!$B$7="",F38<= 'Global Filters'!$B$7)) -> TRUE | AB38: =IF(AND(AA38,X38=1),1,0) -> 1
A39: INIT0038 | B39: API - Feature 38 | C39: API | D39: On Hold | E39: 45265 | F39: 45358 | H39: 13 | I39: 500000 | J39: 288299 | K39: 84 | L39: Critical | M39: 500000 | O39: 25 | P39: Team Delta | Q39: 93 | T39: 211701 | U39: 42.3402 | V39: 0 | X39: 1 | AA39: =AND(OR('Global Filters'!$B$2="",EXACT(TRIM(C39),TRIM('Global Filters'!$B$2))),OR('Global Filters'!$B$3="",EXACT(TRIM(D39),TRIM('Global Filters'!$B$3))),OR('Global Filters'!$B$4="",EXACT(TRIM(L39),TRIM('Global Filters'!$B$4))),OR('Global Filters'!$B$5="",EXACT(TRIM(P39),TRIM('Global Filters'!$B$5))),OR('Global Filters'!$B$6="",E39>= 'Global Filters'!$B$6),OR('Global Filters'!$B$7="",F39<= 'Global Filters'!$B$7)) -> TRUE | AB39: =IF(AND(AA39,X39=1),1,0) -> 1
A40: INIT0039 | B40: Analytics Suite - Feature 39 | C40: Analytics Suite | D40: On Hold | E40: 45256 | F40: 45326 | H40: 10 | I40: 1000000 | J40: 979076 | K40: 70 | L40: Critical | M40: 100000 | O40: 25 | P40: Team Alpha | Q40: 70 | T40: 20924 | U40: 2.0924 | V40: 0 | X40: 1 | AA40: =AND(OR('Global Filters'!$B$2="",EXACT(TRIM(C40),TRIM('Global Filters'!$B$2))),OR('Global Filters'!$B$3="",EXACT(TRIM(D40),TRIM('Global Filters'!$B$3))),OR('Global Filters'!$B$4="",EXACT(TRIM(L40),TRIM('Global Filters'!$B$4))),OR('Global Filters'!$B$5="",EXACT(TRIM(P40),TRIM('Global Filters'!$B$5))),OR('Global Filters'!$B$6="",E40>= 'Global Filters'!$B$6),OR('Global Filters'!$B$7="",F40<= 'Global Filters'!$B$7)) -> TRUE | AB40: =IF(AND(AA40,X40=1),1,0) -> 1
...

Sheet Global Filters
A1: Global Filters | C1: Helper Lists | D1: Product Lines | E1: Status | F1: Priority | G1: Teams
A2: Product Line: | D2: API | E2: In Development | F2: Critical | G2: Team Alpha
A3: Status: | D3: Analytics Suite | E3: Launched | F3: High | G3: Team Beta
A4: Priority: | D4: Data Infrastructure | E4: On Hold | F4: Low | G4: Team Delta
A5: Team: | D5: Mobile App | E5: Planning | F5: Medium | G5: Team Epsilon
A6: Start Date: | D6: Web Platform | E6: Testing | G6: Team Gamma
A7: End Date:

Sheet Executive Summary
A1: Executive Summary KPI Cards
A3: KPI | B3: Value | C3: Notes | E3: Status | F3: Count
A4: Initiatives (Total) | B4: =SUMIF(Data!$AB$2:$AB$96,1) -> 80 | E4: Planning | F4: =SUMPRODUCT(Data!$AB$2:$AB$81,--(Data!$D$2:$D$81="Planning")) -> 18
A5: On-time delivery rate (%) | B5: =IFERROR(SUMPRODUCT(Data!$V$2:$V$96,Data!$AB$2:$AB$96)/SUMPRODUCT(Data!$AB$2:$AB$96),0) -> 0.075 | C5: Average of 1/0 flags | E5: In Development | F5: =SUMPRODUCT(Data!$AB$2:$AB$81,--(Data!$D$2:$D$81="In Development")) -> 13
A6: Budget utilization rate (%) | B6: =IFERROR(SUMPRODUCT(Data!$J$2:$J$96,Data!$AB$2:$AB$96)/SUMPRODUCT(Data!$I$2:$I$96,Data!$AB$2:$AB$96),0) -> 0.72260606 | C6: Spent / Allocated | E6: Testing | F6: =SUMPRODUCT(Data!$AB$2:$AB$81,--(Data!$D$2:$D$81="Testing")) -> 16
A7: Avg. resource utilization (%) | B7: =IFERROR(SUMPRODUCT(Data!$K$2:$K$96,Data!$AB$2:$AB$96)/SUMPRODUCT(Data!$AB$2:$AB$96),0) -> 81.275 | C7: Mean across initiatives | E7: Launched | F7: =SUMPRODUCT(Data!$AB$2:$AB$81,--(Data!$D$2:$D$81="Launched")) -> 18
A8: Expected revenue (Total $) | B8: =SUMPRODUCT(Data!$M$2:$M$96,Data!$AB$2:$AB$96) -> 104200000 | E8: On Hold | F8: =SUMPRODUCT(Data!$AB$2:$AB$81,--(Data!$D$2:$D$81="On Hold")) -> 15
A9: Actual revenue (Total $) | B9: =SUMPRODUCT(Data!$N$2:$N$96,Data!$AB$2:$AB$96) -> 21409447

Sheet Timeline
A1: Initiative Name | B1: All Product Lines | C1: All Statuses | D1: Start Date | E1: Target Completion Date | F1: Actual Completion Date | G1: Planned Duration (days) | H1: Actual Duration (days) | I1: Progress % | J1: Start Offset (days) | P1: Product Line Helper (use sheet filters; slicers in later subtask) | Q1: Product Lines | R1: Statuses | S1: All Product Lines | T1: All Statuses | U1: Include Flag | V1: Start Offset (visible) | W1: Planned Duration (visible) | X1: Actual Duration (visible) | Y1: Planned End Offset (days) | Z1: Actual End Offset (days) | AA1: Planned End Offset (visible) | AB1: Actual End Offset (visible) | AC1: Row Index | AG1: Include
A2: Analytics Suite - Feature 1 | B2: Analytics Suite | C2: Testing | D2: 44971 | E2: 45100 | G2: 129 | I2: 80 | J2: 42 | P2: API | Q2: Analytics Suite | R2: Testing | S2: Select Product Line: | T2: Select Status: | U2: =IF(AND(OR($S$1="All Product Lines",$S$1="",B2=$S$1),OR($T$1="All Statuses",$T$1="",C2=$T$1)),1,0) -> 1 | V2: =IF($AG2=1,$J2,NA()) -> 42 | W2: =IF($AG2=1,$G2,NA()) -> 129 | X2: =IF(AND($AG2=1,ISNUMBER($H2)),$H2,NA()) -> #N/A | Y2: =IF(ISNUMBER(G2),J2+G2,NA()) -> 171 | Z2: =IF(ISNUMBER(H2),J2+H2,NA()) -> #N/A | AA2: =IF($AG2=1,$J2+$G2,NA()) -> 171 | AB2: =IF(AND($AG2=1,ISNUMBER($H2)),$J2+$H2,NA()) -> #N/A | AC2: 1 | AG2: {=IFERROR(INDEX(Data!$AB$2:$AB$81,MATCH(A2,Data!$B$2:$B$81,0)),1)} -> 1
A3: Mobile App - Feature 2 | B3: Mobile App | C3: On Hold | D3: 45139 | E3: 45207 | G3: 68 | I3: 25 | J3: 210 | P3: Analytics Suite | Q3: Mobile App | R3: On Hold | U3: =IF(AND(OR($S$1="All Product Lines",$S$1="",B3=$S$1),OR($T$1="All Statuses",$T$1="",C3=$T$1)),1,0) -> 1 | V3: =IF($AG3=1,$J3,NA()) -> 210 | W3: =IF($AG3=1,$G3,NA()) -> 68 | X3: =IF(AND($AG3=1,ISNUMBER($H3)),$H3,NA()) -> #N/A | Y3: =IF(ISNUMBER(G3),J3+G3,NA()) -> 278 | Z3: =IF(ISNUMBER(H3),J3+H3,NA()) -> #N/A | AA3: =IF($AG3=1,$J3+$G3,NA()) -> 278 | AB3: =IF(AND($AG3=1,ISNUMBER($H3)),$J3+$H3,NA()) -> #N/A | AC3: 2 | AG3: {=IFERROR(INDEX(Data!$AB$2:$AB$81,MATCH(A3,Data!$B$2:$B$81,0)),1)} -> 1
A4: Analytics Suite - Feature 3 | B4: Analytics Suite | C4: Planning | D4: 45103 | E4: 45238 | G4: 135 | I4: 10 | J4: 174 | P4: Data Infrastructure | Q4: Data Infrastructure | R4: Planning | U4: =IF(AND(OR($S$1="All Product Lines",$S$1="",B4=$S$1),OR($T$1="All Statuses",$T$1="",C4=$T$1)),1,0) -> 1 | V4: =IF($AG4=1,$J4,NA()) -> 174 | W4: =IF($AG4=1,$G4,NA()) -> 135 | X4: =IF(AND($AG4=1,ISNUMBER($H4)),$H4,NA()) -> #N/A | Y4: =IF(ISNUMBER(G4),J4+G4,NA()) -> 309 | Z4: =IF(ISNUMBER(H4),J4+H4,NA()) -> #N/A | AA4: =IF($AG4=1,$J4+$G4,NA()) -> 309 | AB4: =IF(AND($AG4=1,ISNUMBER($H4)),$J4+$H4,NA()) -> #N/A | AC4: 3 | AG4: {=IFERROR(INDEX(Data!$AB$2:$AB$81,MATCH(A4,Data!$B$2:$B$81,0)),1)} -> 1
A5: Mobile App - Feature 4 | B5: Mobile App | C5: In Development | D5: 45000 | E5: 45132 | G5: 132 | I5: 50 | J5: 71 | P5: Mobile App | Q5: Web Platform | R5: In Development | U5: =IF(AND(OR($S$1="All Product Lines",$S$1="",B5=$S$1),OR($T$1="All Statuses",$T$1="",C5=$T$1)),1,0) -> 1 | V5: =IF($AG5=1,$J5,NA()) -> 71 | W5: =IF($AG5=1,$G5,NA()) -> 132 | X5: =IF(AND($AG5=1,ISNUMBER($H5)),$H5,NA()) -> #N/A | Y5: =IF(ISNUMBER(G5),J5+G5,NA()) -> 203 | Z5: =IF(ISNUMBER(H5),J5+H5,NA()) -> #N/A | AA5: =IF($AG5=1,$J5+$G5,NA()) -> 203 | AB5: =IF(AND($AG5=1,ISNUMBER($H5)),$J5+$H5,NA()) -> #N/A | AC5: 4 | AG5: {=IFERROR(INDEX(Data!$AB$2:$AB$81,MATCH(A5,Data!$B$2:$B$81,0)),1)} -> 1
A6: Data Infrastructure - Feature 5 | B6: Data Infrastructure | C6: Testing | D6: 45099 | E6: 45206 | G6: 107 | I6: 80 | J6: 170 | P6: Web Platform | Q6: API | R6: Launched | U6: =IF(AND(OR($S$1="All Product Lines",$S$1="",B6=$S$1),OR($T$1="All Statuses",$T$1="",C6=$T$1)),1,0) -> 1 | V6: =IF($AG6=1,$J6,NA()) -> 170 | W6: =IF($AG6=1,$G6,NA()) -> 107 | X6: =IF(AND($AG6=1,ISNUMBER($H6)),$H6,NA()) -> #N/A | Y6: =IF(ISNUMBER(G6),J6+G6,NA()) -> 277 | Z6: =IF(ISNUMBER(H6),J6+H6,NA()) -> #N/A | AA6: =IF($AG6=1,$J6+$G6,NA()) -> 277 | AB6: =IF(AND($AG6=1,ISNUMBER($H6)),$J6+$H6,NA()) -> #N/A | AC6: 5 | AG6: {=IFERROR(INDEX(Data!$AB$2:$AB$81,MATCH(A6,Data!$B$2:$B$81,0)),1)} -> 1
A7: Web Platform - Feature 6 | B7: Web Platform | C7: Testing | D7: 45064 | E7: 45200 | G7: 136 | I7: 80 | J7: 135 | U7: =IF(AND(OR($S$1="All Product Lines",$S$1="",B7=$S$1),OR($T$1="All Statuses",$T$1="",C7=$T$1)),1,0) -> 1 | V7: =IF($AG7=1,$J7,NA()) -> 135 | W7: =IF($AG7=1,$G7,NA()) -> 136 | X7: =IF(AND($AG7=1,ISNUMBER($H7)),$H7,NA()) -> #N/A | Y7: =IF(ISNUMBER(G7),J7+G7,NA()) -> 271 | Z7: =IF(ISNUMBER(H7),J7+H7,NA()) -> #N/A | AA7: =IF($AG7=1,$J7+$G7,NA()) -> 271 | AB7: =IF(AND($AG7=1,ISNUMBER($H7)),$J7+$H7,NA()) -> #N/A | AC7: 6 | AG7: {=IFERROR(INDEX(Data!$AB$2:$AB$81,MATCH(A7,Data!$B$2:$B$81,0)),1)} -> 1
A8: Data Infrastructure - Feature 7 | B8: Data Infrastructure | C8: Launched | D8: 45190 | E8: 45260 | F8: 45263 | G8: 70 | H8: 73 | I8: 100 | J8: 261 | U8: =IF(AND(OR($S$1="All Product Lines",$S$1="",B8=$S$1),OR($T$1="All Statuses",$T$1="",C8=$T$1)),1,0) -> 1 | V8: =IF($AG8=1,$J8,NA()) -> 261 | W8: =IF($AG8=1,$G8,NA()) -> 70 | X8: =IF(AND($AG8=1,ISNUMBER($H8)),$H8,NA()) -> 73 | Y8: =IF(ISNUMBER(G8),J8+G8,NA()) -> 331 | Z8: =IF(ISNUMBER(H8),J8+H8,NA()) -> 334 | AA8: =IF($AG8=1,$J8+$G8,NA()) -> 331 | AB8: =IF(AND($AG8=1,ISNUMBER($H8)),$J8+$H8,NA()) -> 334 | AC8: 7 | AG8: {=IFERROR(INDEX(Data!$AB$2:$AB$81,MATCH(A8,Data!$B$2:$B$81,0)),1)} -> 1
A9: Web Platform - Feature 8 | B9: Web Platform | C9: Planning | D9: 45160 | E9: 45202 | G9: 42 | I9: 10 | J9: 231 | U9: =IF(AND(OR($S$1="All Product Lines",$S$1="",B9=$S$1),OR($T$1="All Statuses",$T$1="",C9=$T$1)),1,0) -> 1 | V9: =IF($AG9=1,$J9,NA()) -> 231 | W9: =IF($AG9=1,$G9,NA()) -> 42 | X9: =IF(AND($AG9=1,ISNUMBER($H9)),$H9,NA()) -> #N/A | Y9: =IF(ISNUMBER(G9),J9+G9,NA()) -> 273 | Z9: =IF(ISNUMBER(H9),J9+H9,NA()) -> #N/A | AA9: =IF($AG9=1,$J9+$G9,NA()) -> 273 | AB9: =IF(AND($AG9=1,ISNUMBER($H9)),$J9+$H9,NA()) -> #N/A | AC9: 8 | AG9: {=IFERROR(INDEX(Data!$AB$2:$AB$81,MATCH(A9,Data!$B$2:$B$81,0)),1)} -> 1
A10: Analytics Suite - Feature 9 | B10: Analytics Suite | C10: Launched | D10: 45050 | E10: 45175 | F10: 45177 | G10: 125 | H10: 127 | I10: 100 | J10: 121 | U10: =IF(AND(OR($S$1="All Product Lines",$S$1="",B10=$S$1),OR($T$1="All Statuses",$T$1="",C10=$T$1)),1,0) -> 1 | V10: =IF($AG10=1,$J10,NA()) -> 121 | W10: =IF($AG10=1,$G10,NA()) -> 125 | X10: =IF(AND($AG10=1,ISNUMBER($H10)),$H10,NA()) -> 127 | Y10: =IF(ISNUMBER(G10),J10+G10,NA()) -> 246 | Z10: =IF(ISNUMBER(H10),J10+H10,NA()) -> 248 | AA10: =IF($AG10=1,$J10+$G10,NA()) -> 246 | AB10: =IF(AND($AG10=1,ISNUMBER($H10)),$J10+$H10,NA()) -> 248 | AC10: 9 | AG10: {=IFERROR(INDEX(Data!$AB$2:$AB$81,MATCH(A10,Data!$B$2:$B$81,0)),1)} -> 1
A11: API - Feature 10 | B11: API | C11: Planning | D11: 45124 | E11: 45166 | G11: 42 | I11: 10 | J11: 195 | U11: =IF(AND(OR($S$1="All Product Lines",$S$1="",B11=$S$1),OR($T$1="All Statuses",$T$1="",C11=$T$1)),1,0) -> 1 | V11: =IF($AG11=1,$J11,NA()) -> 195 | W11: =IF($AG11=1,$G11,NA()) -> 42 | X11: =IF(AND($AG11=1,ISNUMBER($H11)),$H11,NA()) -> #N/A | Y11: =IF(ISNUMBER(G11),J11+G11,NA()) -> 237 | Z11: =IF(ISNUMBER(H11),J11+H11,NA()) -> #N/A | AA11: =IF($AG11=1,$J11+$G11,NA()) -> 237 | AB11: =IF(AND($AG11=1,ISNUMBER($H11)),$J11+$H11,NA()) -> #N/A | AC11: 10 | AG11: {=IFERROR(INDEX(Data!$AB$2:$AB$81,MATCH(A11,Data!$B$2:$B$81,0)),1)} -> 1
A12: Web Platform - Feature 11 | B12: Web Platform | C12: In Development | D12: 45189 | E12: 45224 | G12: 35 | I12: 50 | J12: 260 | U12: =IF(AND(OR($S$1="All Product Lines",$S$1="",B12=$S$1),OR($T$1="All Statuses",$T$1="",C12=$T$1)),1,0) -> 1 | V12: =IF($AG12=1,$J12,NA()) -> 260 | W12: =IF($AG12=1,$G12,NA()) -> 35 | X12: =IF(AND($AG12=1,ISNUMBER($H12)),$H12,NA()) -> #N/A | Y12: =IF(ISNUMBER(G12),J12+G12,NA()) -> 295 | Z12: =IF(ISNUMBER(H12),J12+H12,NA()) -> #N/A | AA12: =IF($AG12=1,$J12+$G12,NA()) -> 295 | AB12: =IF(AND($AG12=1,ISNUMBER($H12)),$J12+$H12,NA()) -> #N/A | AC12: 11 | AG12: {=IFERROR(INDEX(Data!$AB$2:$AB$81,MATCH(A12,Data!$B$2:$B$81,0)),1)} -> 1
A13: Web Platform - Feature 12 | B13: Web Platform | C13: Testing | D13: 45143 | E13: 45269 | G13: 126 | I13: 80 | J13: 214 | U13: =IF(AND(OR($S$1="All Product Lines",$S$1="",B13=$S$1),OR($T$1="All Statuses",$T$1="",C13=$T$1)),1,0) -> 1 | V13: =IF($AG13=1,$J13,NA()) -> 214 | W13: =IF($AG13=1,$G13,NA()) -> 126 | X13: =IF(AND($AG13=1,ISNUMBER($H13)),$H13,NA()) -> #N/A | Y13: =IF(ISNUMBER(G13),J13+G13,NA()) -> 340 | Z13: =IF(ISNUMBER(H13),J13+H13,NA()) -> #N/A | AA13: =IF($AG13=1,$J13+$G13,NA()) -> 340 | AB13: =IF(AND($AG13=1,ISNUMBER($H13)),$J13+$H13,NA()) -> #N/A | AC13: 12 | AG13: {=IFERROR(INDEX(Data!$AB$2:$AB$81,MATCH(A13,Data!$B$2:$B$81,0)),1)} -> 1
A14: Analytics Suite - Feature 13 | B14: Analytics Suite | C14: On Hold | D14: 44979 | E14: 45010 | G14: 31 | I14: 25 | J14: 50 | U14: =IF(AND(OR($S$1="All Product Lines",$S$1="",B14=$S$1),OR($T$1="All Statuses",$T$1="",C14=$T$1)),1,0) -> 1 | V14: =IF($AG14=1,$J14,NA()) -> 50 | W14: =IF($AG14=1,$G14,NA()) -> 31 | X14: =IF(AND($AG14=1,ISNUMBER($H14)),$H14,NA()) -> #N/A | Y14: =IF(ISNUMBER(G14),J14+G14,NA()) -> 81 | Z14: =IF(ISNUMBER(H14),J14+H14,NA()) -> #N/A | AA14: =IF($AG14=1,$J14+$G14,NA()) -> 81 | AB14: =IF(AND($AG14=1,ISNUMBER($H14)),$J14+$H14,NA()) -> #N/A | AC14: 13 | AG14: {=IFERROR(INDEX(Data!$AB$2:$AB$81,MATCH(A14,Data!$B$2:$B$81,0)),1)} -> 1
A15: API - Feature 14 | B15: API | C15: Planning | D15: 45099 | E15: 45199 | G15: 100 | I15: 10 | J15: 170 | U15: =IF(AND(OR($S$1="All Product Lines",$S$1="",B15=$S$1),OR($T$1="All Statuses",$T$1="",C15=$T$1)),1,0) -> 1 | V15: =IF($AG15=1,$J15,NA()) -> 170 | W15: =IF($AG15=1,$G15,NA()) -> 100 | X15: =IF(AND($AG15=1,ISNUMBER($H15)),$H15,NA()) -> #N/A | Y15: =IF(ISNUMBER(G15),J15+G15,NA()) -> 270 | Z15: =IF(ISNUMBER(H15),J15+H15,NA()) -> #N/A | AA15: =IF($AG15=1,$J15+$G15,NA()) -> 270 | AB15: =IF(AND($AG15=1,ISNUMBER($H15)),$J15+$H15,NA()) -> #N/A | AC15: 14 | AG15: {=IFERROR(INDEX(Data!$AB$2:$AB$81,MATCH(A15,Data!$B$2:$B$81,0)),1)} -> 1
A16: Web Platform - Feature 15 | B16: Web Platform | C16: On Hold | D16: 45234 | E16: 45367 | G16: 133 | I16: 25 | J16: 305 | U16: =IF(AND(OR($S$1="All Product Lines",$S$1="",B16=$S$1),OR($T$1="All Statuses",$T$1="",C16=$T$1)),1,0) -> 1 | V16: =IF($AG16=1,$J16,NA()) -> 305 | W16: =IF($AG16=1,$G16,NA()) -> 133 | X16: =IF(AND($AG16=1,ISNUMBER($H16)),$H16,NA()) -> #N/A | Y16: =IF(ISNUMBER(G16),J16+G16,NA()) -> 438 | Z16: =IF(ISNUMBER(H16),J16+H16,NA()) -> #N/A | AA16: =IF($AG16=1,$J16+$G16,NA()) -> 438 | AB16: =IF(AND($AG16=1,ISNUMBER($H16)),$J16+$H16,NA()) -> #N/A | AC16: 15 | AG16: {=IFERROR(INDEX(Data!$AB$2:$AB$81,MATCH(A16,Data!$B$2:$B$81,0)),1)} -> 1
A17: API - Feature 16 | B17: API | C17: Testing | D17: 45125 | E17: 45164 | G17: 39 | I17: 80 | J17: 196 | U17: =IF(AND(OR($S$1="All Product Lines",$S$1="",B17=$S$1),OR($T$1="All Statuses",$T$1="",C17=$T$1)),1,0) -> 1 | V17: =IF($AG17=1,$J17,NA()) -> 196 | W17: =IF($AG17=1,$G17,NA()) -> 39 | X17: =IF(AND($AG17=1,ISNUMBER($H17)),$H17,NA()) -> #N/A | Y17: =IF(ISNUMBER(G17),J17+G17,NA()) -> 235 | Z17: =IF(ISNUMBER(H17),J17+H17,NA()) -> #N/A | AA17: =IF($AG17=1,$J17+$G17,NA()) -> 235 | AB17: =IF(AND($AG17=1,ISNUMBER($H17)),$J17+$H17,NA()) -> #N/A | AC17: 16 | AG17: {=IFERROR(INDEX(Data!$AB$2:$AB$81,MATCH(A17,Data!$B$2:$B$81,0)),1)} -> 1
A18: Web Platform - Feature 17 | B18: Web Platform | C18: On Hold | D18: 45186 | E18: 45292 | G18: 106 | I18: 25 | J18: 257 | U18: =IF(AND(OR($S$1="All Product Lines",$S$1="",B18=$S$1),OR($T$1="All Statuses",$T$1="",C18=$T$1)),1,0) -> 1 | V18: =IF($AG18=1,$J18,NA()) -> 257 | W18: =IF($AG18=1,$G18,NA()) -> 106 | X18: =IF(AND($AG18=1,ISNUMBER($H18)),$H18,NA()) -> #N/A | Y18: =IF(ISNUMBER(G18),J18+G18,NA()) -> 363 | Z18: =IF(ISNUMBER(H18),J18+H18,NA()) -> #N/A | AA18: =IF($AG18=1,$J18+$G18,NA()) -> 363 | AB18: =IF(AND($AG18=1,ISNUMBER($H18)),$J18+$H18,NA()) -> #N/A | AC18: 17 | AG18: {=IFERROR(INDEX(Data!$AB$2:$AB$81,MATCH(A18,Data!$B$2:$B$81,0)),1)} -> 1
A19: Mobile App - Feature 18 | B19: Mobile App | C19: Launched | D19: 45213 | E19: 45289 | F19: 45315 | G19: 76 | H19: 102 | I19: 100 | J19: 284 | U19: =IF(AND(OR($S$1="All Product Lines",$S$1="",B19=$S$1),OR($T$1="All Statuses",$T$1="",C19=$T$1)),1,0) -> 1 | V19: =IF($AG19=1,$J19,NA()) -> 284 | W19: =IF($AG19=1,$G19,NA()) -> 76 | X19: =IF(AND($AG19=1,ISNUMBER($H19)),$H19,NA()) -> 102 | Y19: =IF(ISNUMBER(G19),J19+G19,NA()) -> 360 | Z19: =IF(ISNUMBER(H19),J19+H19,NA()) -> 386 | AA19: =IF($AG19=1,$J19+$G19,NA()) -> 360 | AB19: =IF(AND($AG19=1,ISNUMBER($H19)),$J19+$H19,NA()) -> 386 | AC19: 18 | AG19: {=IFERROR(INDEX(Data!$AB$2:$AB$81,MATCH(A19,Data!$B$2:$B$81,0)),1)} -> 1
A20: API - Feature 19 | B20: API | C20: Testing | D20: 45077 | E20: 45225 | G20: 148 | I20: 80 | J20: 148 | U20: =IF(AND(OR($S$1="All Product Lines",$S$1="",B20=$S$1),OR($T$1="All Statuses",$T$1="",C20=$T$1)),1,0) -> 1 | V20: =IF($AG20=1,$J20,NA()) -> 148 | W20: =IF($AG20=1,$G20,NA()) -> 148 | X20: =IF(AND($AG20=1,ISNUMBER($H20)),$H20,NA()) -> #N/A | Y20: =IF(ISNUMBER(G20),J20+G20,NA()) -> 296 | Z20: =IF(ISNUMBER(H20),J20+H20,NA()) -> #N/A | AA20: =IF($AG20=1,$J20+$G20,NA()) -> 296 | AB20: =IF(AND($AG20=1,ISNUMBER($H20)),$J20+$H20,NA()) -> #N/A | AC20: 19 | AG20: {=IFERROR(INDEX(Data!$AB$2:$AB$81,MATCH(A20,Data!$B$2:$B$81,0)),1)} -> 1
A21: Data Infrastructure - Feature 20 | B21: Data Infrastructure | C21: In Development | D21: 45198 | E21: 45304 | G21: 106 | I21: 50 | J21: 269 | U21: =IF(AND(OR($S$1="All Product Lines",$S$1="",B21=$S$1),OR($T$1="All Statuses",$T$1="",C21=$T$1)),1,0) -> 1 | V21: =IF($AG21=1,$J21,NA()) -> 269 | W21: =IF($AG21=1,$G21,NA()) -> 106 | X21: =IF(AND($AG21=1,ISNUMBER($H21)),$H21,NA()) -> #N/A | Y21: =IF(ISNUMBER(G21),J21+G21,NA()) -> 375 | Z21: =IF(ISNUMBER(H21),J21+H21,NA()) -> #N/A | AA21: =IF($AG21=1,$J21+$G21,NA()) -> 375 | AB21: =IF(AND($AG21=1,ISNUMBER($H21)),$J21+$H21,NA()) -> #N/A | AC21: 20 | AG21: {=IFERROR(INDEX(Data!$AB$2:$AB$81,MATCH(A21,Data!$B$2:$B$81,0)),1)} -> 1
A22: API - Feature 21 | B22: API | C22: Launched | D22: 45088 | E22: 45164 | F22: 45200 | G22: 76 | H22: 112 | I22: 100 | J22: 159 | U22: =IF(AND(OR($S$1="All Product Lines",$S$1="",B22=$S$1),OR($T$1="All Statuses",$T$1="",C22=$T$1)),1,0) -> 1 | V22: =IF($AG22=1,$J22,NA()) -> 159 | W22: =IF($AG22=1,$G22,NA()) -> 76 | X22: =IF(AND($AG22=1,ISNUMBER($H22)),$H22,NA()) -> 112 | Y22: =IF(ISNUMBER(G22),J22+G22,NA()) -> 235 | Z22: =IF(ISNUMBER(H22),J22+H22,NA()) -> 271 | AA22: =IF($AG22=1,$J22+$G22,NA()) -> 235 | AB22: =IF(AND($AG22=1,ISNUMBER($H22)),$J22+$H22,NA()) -> 271 | AC22: 21 | AG22: {=IFERROR(INDEX(Data!$AB$2:$AB$81,MATCH(A22,Data!$B$2:$B$81,0)),1)} -> 1
A23: API - Feature 22 | B23: API | C23: In Development | D23: 45008 | E23: 45163 | G23: 155 | I23: 50 | J23: 79 | U23: =IF(AND(OR($S$1="All Product Lines",$S$1="",B23=$S$1),OR($T$1="All Statuses",$T$1="",C23=$T$1)),1,0) -> 1 | V23: =IF($AG23=1,$J23,NA()) -> 79 | W23: =IF($AG23=1,$G23,NA()) -> 155 | X23: =IF(AND($AG23=1,ISNUMBER($H23)),$H23,NA()) -> #N/A | Y23: =IF(ISNUMBER(G23),J23+G23,NA()) -> 234 | Z23: =IF(ISNUMBER(H23),J23+H23,NA()) -> #N/A | AA23: =IF($AG23=1,$J23+$G23,NA()) -> 234 | AB23: =IF(AND($AG23=1,ISNUMBER($H23)),$J23+$H23,NA()) -> #N/A | AC23: 22 | AG23: {=IFERROR(INDEX(Data!$AB$2:$AB$81,MATCH(A23,Data!$B$2:$B$81,0)),1)} -> 1
A24: Data Infrastructure - Feature 23 | B24: Data Infrastructure | C24: Launched | D24: 44929 | E24: 44968 | F24: 44968 | G24: 39 | H24: 39 | I24: 100 | J24: 0 | U24: =IF(AND(OR($S$1="All Product Lines",$S$1="",B24=$S$1),OR($T$1="All Statuses",$T$1="",C24=$T$1)),1,0) -> 1 | V24: =IF($AG24=1,$J24,NA()) -> 0 | W24: =IF($AG24=1,$G24,NA()) -> 39 | X24: =IF(AND($AG24=1,ISNUMBER($H24)),$H24,NA()) -> 39 | Y24: =IF(ISNUMBER(G24),J24+G24,NA()) -> 39 | Z24: =IF(ISNUMBER(H24),J24+H24,NA()) -> 39 | AA24: =IF($AG24=1,$J24+$G24,NA()) -> 39 | AB24: =IF(AND($AG24=1,ISNUMBER($H24)),$J24+$H24,NA()) -> 39 | AC24: 23 | AG24: {=IFERROR(INDEX(Data!$AB$2:$AB$81,MATCH(A24,Data!$B$2:$B$81,0)),1)} -> 1
A25: Mobile App - Feature 24 | B25: Mobile App | C25: In Development | D25: 45086 | E25: 45149 | G25: 63 | I25: 50 | J25: 157 | U25: =IF(AND(OR($S$1="All Product Lines",$S$1="",B25=$S$1),OR($T$1="All Statuses",$T$1="",C25=$T$1)),1,0) -> 1 | V25: =IF($AG25=1,$J25,NA()) -> 157 | W25: =IF($AG25=1,$G25,NA()) -> 63 | X25: =IF(AND($AG25=1,ISNUMBER($H25)),$H25,NA()) -> #N/A | Y25: =IF(ISNUMBER(G25),J25+G25,NA()) -> 220 | Z25: =IF(ISNUMBER(H25),J25+H25,NA()) -> #N/A | AA25: =IF($AG25=1,$J25+$G25,NA()) -> 220 | AB25: =IF(AND($AG25=1,ISNUMBER($H25)),$J25+$H25,NA()) -> #N/A | AC25: 24 | AG25: {=IFERROR(INDEX(Data!$AB$2:$AB$81,MATCH(A25,Data!$B$2:$B$81,0)),1)} -> 1
A26: Mobile App - Feature 25 | B26: Mobile App | C26: Planning | D26: 45160 | E26: 45323 | G26: 163 | I26: 10 | J26: 231 | U26: =IF(AND(OR($S$1="All Product Lines",$S$1="",B26=$S$1),OR($T$1="All Statuses",$T$1="",C26=$T$1)),1,0) -> 1 | V26: =IF($AG26=1,$J26,NA()) -> 231 | W26: =IF($AG26=1,$G26,NA()) -> 163 | X26: =IF(AND($AG26=1,ISNUMBER($H26)),$H26,NA()) -> #N/A | Y26: =IF(ISNUMBER(G26),J26+G26,NA()) -> 394 | Z26: =IF(ISNUMBER(H26),J26+H26,NA()) -> #N/A | AA26: =IF($AG26=1,$J26+$G26,NA()) -> 394 | AB26: =IF(AND($AG26=1,ISNUMBER($H26)),$J26+$H26,NA()) -> #N/A | AC26: 25 | AG26: {=IFERROR(INDEX(Data!$AB$2:$AB$81,MATCH(A26,Data!$B$2:$B$81,0)),1)} -> 1
A27: Data Infrastructure - Feature 26 | B27: Data Infrastructure | C27: Testing | D27: 45133 | E27: 45167 | G27: 34 | I27: 80 | J27: 204 | U27: =IF(AND(OR($S$1="All Product Lines",$S$1="",B27=$S$1),OR($T$1="All Statuses",$T$1="",C27=$T$1)),1,0) -> 1 | V27: =IF($AG27=1,$J27,NA()) -> 204 | W27: =IF($AG27=1,$G27,NA()) -> 34 | X27: =IF(AND($AG27=1,ISNUMBER($H27)),$H27,NA()) -> #N/A | Y27: =IF(ISNUMBER(G27),J27+G27,NA()) -> 238 | Z27: =IF(ISNUMBER(H27),J27+H27,NA()) -> #N/A | AA27: =IF($AG27=1,$J27+$G27,NA()) -> 238 | AB27: =IF(AND($AG27=1,ISNUMBER($H27)),$J27+$H27,NA()) -> #N/A | AC27: 26 | AG27: {=IFERROR(INDEX(Data!$AB$2:$AB$81,MATCH(A27,Data!$B$2:$B$81,0)),1)} -> 1
A28: Analytics Suite - Feature 27 | B28: Analytics Suite | C28: On Hold | D28: 45114 | E28: 45153 | G28: 39 | I28: 25 | J28: 185 | U28: =IF(AND(OR($S$1="All Product Lines",$S$1="",B28=$S$1),OR($T$1="All Statuses",$T$1="",C28=$T$1)),1,0) -> 1 | V28: =IF($AG28=1,$J28,NA()) -> 185 | W28: =IF($AG28=1,$G28,NA()) -> 39 | X28: =IF(AND($AG28=1,ISNUMBER($H28)),$H28,NA()) -> #N/A | Y28: =IF(ISNUMBER(G28),J28+G28,NA()) -> 224 | Z28: =IF(ISNUMBER(H28),J28+H28,NA()) -> #N/A | AA28: =IF($AG28=1,$J28+$G28,NA()) -> 224 | AB28: =IF(AND($AG28=1,ISNUMBER($H28)),$J28+$H28,NA()) -> #N/A | AC28: 27 | AG28: {=IFERROR(INDEX(Data!$AB$2:$AB$81,MATCH(A28,Data!$B$2:$B$81,0)),1)} -> 1
A29: Analytics Suite - Feature 28 | B29: Analytics Suite | C29: Planning | D29: 44951 | E29: 45010 | G29: 59 | I29: 10 | J29: 22 | U29: =IF(AND(OR($S$1="All Product Lines",$S$1="",B29=$S$1),OR($T$1="All Statuses",$T$1="",C29=$T$1)),1,0) -> 1 | V29: =IF($AG29=1,$J29,NA()) -> 22 | W29: =IF($AG29=1,$G29,NA()) -> 59 | X29: =IF(AND($AG29=1,ISNUMBER($H29)),$H29,NA()) -> #N/A | Y29: =IF(ISNUMBER(G29),J29+G29,NA()) -> 81 | Z29: =IF(ISNUMBER(H29),J29+H29,NA()) -> #N/A | AA29: =IF($AG29=1,$J29+$G29,NA()) -> 81 | AB29: =IF(AND($AG29=1,ISNUMBER($H29)),$J29+$H29,NA()) -> #N/A | AC29: 28 | AG29: {=IFERROR(INDEX(Data!$AB$2:$AB$81,MATCH(A29,Data!$B$2:$B$81,0)),1)} -> 1
A30: Data Infrastructure - Feature 29 | B30: Data Infrastructure | C30: In Development | D30: 45081 | E30: 45218 | G30: 137 | I30: 50 | J30: 152 | U30: =IF(AND(OR($S$1="All Product Lines",$S$1="",B30=$S$1),OR($T$1="All Statuses",$T$1="",C30=$T$1)),1,0) -> 1 | V30: =IF($AG30=1,$J30,NA()) -> 152 | W30: =IF($AG30=1,$G30,NA()) -> 137 | X30: =IF(AND($AG30=1,ISNUMBER($H30)),$H30,NA()) -> #N/A | Y30: =IF(ISNUMBER(G30),J30+G30,NA()) -> 289 | Z30: =IF(ISNUMBER(H30),J30+H30,NA()) -> #N/A | AA30: =IF($AG30=1,$J30+$G30,NA()) -> 289 | AB30: =IF(AND($AG30=1,ISNUMBER($H30)),$J30+$H30,NA()) -> #N/A | AC30: 29 | AG30: {=IFERROR(INDEX(Data!$AB$2:$AB$81,MATCH(A30,Data!$B$2:$B$81,0)),1)} -> 1
A31: Data Infrastructure - Feature 30 | B31: Data Infrastructure | C31: Planning | D31: 44985 | E31: 45042 | G31: 57 | I31: 10 | J31: 56 | U31: =IF(AND(OR($S$1="All Product Lines",$S$1="",B31=$S$1),OR($T$1="All Statuses",$T$1="",C31=$T$1)),1,0) -> 1 | V31: =IF($AG31=1,$J31,NA()) -> 56 | W31: =IF($AG31=1,$G31,NA()) -> 57 | X31: =IF(AND($AG31=1,ISNUMBER($H31)),$H31,NA()) -> #N/A | Y31: =IF(ISNUMBER(G31),J31+G31,NA()) -> 113 | Z31: =IF(ISNUMBER(H31),J31+H31,NA()) -> #N/A | AA31: =IF($AG31=1,$J31+$G31,NA()) -> 113 | AB31: =IF(AND($AG31=1,ISNUMBER($H31)),$J31+$H31,NA()) -> #N/A | AC31: 30 | AG31: {=IFERROR(INDEX(Data!$AB$2:$AB$81,MATCH(A31,Data!$B$2:$B$81,0)),1)} -> 1
A32: API - Feature 31 | B32: API | C32: Launched | D32: 44947 | E32: 45117 | F32: 45115 | G32: 170 | H32: 168 | I32: 100 | J32: 18 | U32: =IF(AND(OR($S$1="All Product Lines",$S$1="",B32=$S$1),OR($T$1="All Statuses",$T$1="",C32=$T$1)),1,0) -> 1 | V32: =IF($AG32=1,$J32,NA()) -> 18 | W32: =IF($AG32=1,$G32,NA()) -> 170 | X32: =IF(AND($AG32=1,ISNUMBER($H32)),$H32,NA()) -> 168 | Y32: =IF(ISNUMBER(G32),J32+G32,NA()) -> 188 | Z32: =IF(ISNUMBER(H32),J32+H32,NA()) -> 186 | AA32: =IF($AG32=1,$J32+$G32,NA()) -> 188 | AB32: =IF(AND($AG32=1,ISNUMBER($H32)),$J32+$H32,NA()) -> 186 | AC32: 31 | AG32: {=IFERROR(INDEX(Data!$AB$2:$AB$81,MATCH(A32,Data!$B$2:$B$81,0)),1)} -> 1
A33: Analytics Suite - Feature 32 | B33: Analytics Suite | C33: Launched | D33: 45188 | E33: 45237 | F33: 45248 | G33: 49 | H33: 60 | I33: 100 | J33: 259 | U33: =IF(AND(OR($S$1="All Product Lines",$S$1="",B33=$S$1),OR($T$1="All Statuses",$T$1="",C33=$T$1)),1,0) -> 1 | V33: =IF($AG33=1,$J33,NA()) -> 259 | W33: =IF($AG33=1,$G33,NA()) -> 49 | X33: =IF(AND($AG33=1,ISNUMBER($H33)),$H33,NA()) -> 60 | Y33: =IF(ISNUMBER(G33),J33+G33,NA()) -> 308 | Z33: =IF(ISNUMBER(H33),J33+H33,NA()) -> 319 | AA33: =IF($AG33=1,$J33+$G33,NA()) -> 308 | AB33: =IF(AND($AG33=1,ISNUMBER($H33)),$J33+$H33,NA()) -> 319 | AC33: 32 | AG33: {=IFERROR(INDEX(Data!$AB$2:$AB$81,MATCH(A33,Data!$B$2:$B$81,0)),1)} -> 1
A34: Mobile App - Feature 33 | B34: Mobile App | C34: In Development | D34: 45111 | E34: 45221 | G34: 110 | I34: 50 | J34: 182 | U34: =IF(AND(OR($S$1="All Product Lines",$S$1="",B34=$S$1),OR($T$1="All Statuses",$T$1="",C34=$T$1)),1,0) -> 1 | V34: =IF($AG34=1,$J34,NA()) -> 182 | W34: =IF($AG34=1,$G34,NA()) -> 110 | X34: =IF(AND($AG34=1,ISNUMBER($H34)),$H34,NA()) -> #N/A | Y34: =IF(ISNUMBER(G34),J34+G34,NA()) -> 292 | Z34: =IF(ISNUMBER(H34),J34+H34,NA()) -> #N/A | AA34: =IF($AG34=1,$J34+$G34,NA()) -> 292 | AB34: =IF(AND($AG34=1,ISNUMBER($H34)),$J34+$H34,NA()) -> #N/A | AC34: 33 | AG34: {=IFERROR(INDEX(Data!$AB$2:$AB$81,MATCH(A34,Data!$B$2:$B$81,0)),1)} -> 1
A35: Web Platform - Feature 34 | B35: Web Platform | C35: In Development | D35: 45151 | E35: 45249 | G35: 98 | I35: 50 | J35: 222 | U35: =IF(AND(OR($S$1="All Product Lines",$S$1="",B35=$S$1),OR($T$1="All Statuses",$T$1="",C35=$T$1)),1,0) -> 1 | V35: =IF($AG35=1,$J35,NA()) -> 222 | W35: =IF($AG35=1,$G35,NA()) -> 98 | X35: =IF(AND($AG35=1,ISNUMBER($H35)),$H35,NA()) -> #N/A | Y35: =IF(ISNUMBER(G35),J35+G35,NA()) -> 320 | Z35: =IF(ISNUMBER(H35),J35+H35,NA()) -> #N/A | AA35: =IF($AG35=1,$J35+$G35,NA()) -> 320 | AB35: =IF(AND($AG35=1,ISNUMBER($H35)),$J35+$H35,NA()) -> #N/A | AC35: 34 | AG35: {=IFERROR(INDEX(Data!$AB$2:$AB$81,MATCH(A35,Data!$B$2:$B$81,0)),1)} -> 1
A36: Data Infrastructure - Feature 35 | B36: Data Infrastructure | C36: Launched | D36: 45124 | E36: 45276 | F36: 45322 | G36: 152 | H36: 198 | I36: 100 | J36: 195 | U36: =IF(AND(OR($S$1="All Product Lines",$S$1="",B36=$S$1),OR($T$1="All Statuses",$T$1="",C36=$T$1)),1,0) -> 1 | V36: =IF($AG36=1,$J36,NA()) -> 195 | W36: =IF($AG36=1,$G36,NA()) -> 152 | X36: =IF(AND($AG36=1,ISNUMBER($H36)),$H36,NA()) -> 198 | Y36: =IF(ISNUMBER(G36),J36+G36,NA()) -> 347 | Z36: =IF(ISNUMBER(H36),J36+H36,NA()) -> 393 | AA36: =IF($AG36=1,$J36+$G36,NA()) -> 347 | AB36: =IF(AND($AG36=1,ISNUMBER($H36)),$J36+$H36,NA()) -> 393 | AC36: 35 | AG36: {=IFERROR(INDEX(Data!$AB$2:$AB$81,MATCH(A36,Data!$B$2:$B$81,0)),1)} -> 1
A37: Analytics Suite - Feature 36 | B37: Analytics Suite | C37: Launched | D37: 45239 | E37: 45366 | F37: 45410 | G37: 127 | H37: 171 | I37: 100 | J37: 310 | U37: =IF(AND(OR($S$1="All Product Lines",$S$1="",B37=$S$1),OR($T$1="All Statuses",$T$1="",C37=$T$1)),1,0) -> 1 | V37: =IF($AG37=1,$J37,NA()) -> 310 | W37: =IF($AG37=1,$G37,NA()) -> 127 | X37: =IF(AND($AG37=1,ISNUMBER($H37)),$H37,NA()) -> 171 | Y37: =IF(ISNUMBER(G37),J37+G37,NA()) -> 437 | Z37: =IF(ISNUMBER(H37),J37+H37,NA()) -> 481 | AA37: =IF($AG37=1,$J37+$G37,NA()) -> 437 | AB37: =IF(AND($AG37=1,ISNUMBER($H37)),$J37+$H37,NA()) -> 481 | AC37: 36 | AG37: {=IFERROR(INDEX(Data!$AB$2:$AB$81,MATCH(A37,Data!$B$2:$B$81,0)),1)} -> 1
A38: Mobile App - Feature 37 | B38: Mobile App | C38: Launched | D38: 44959 | E38: 45055 | F38: 45050 | G38: 96 | H38: 91 | I38: 100 | J38: 30 | U38: =IF(AND(OR($S$1="All Product Lines",$S$1="",B38=$S$1),OR($T$1="All Statuses",$T$1="",C38=$T$1)),1,0) -> 1 | V38: =IF($AG38=1,$J38,NA()) -> 30 | W38: =IF($AG38=1,$G38,NA()) -> 96 | X38: =IF(AND($AG38=1,ISNUMBER($H38)),$H38,NA()) -> 91 | Y38: =IF(ISNUMBER(G38),J38+G38,NA()) -> 126 | Z38: =IF(ISNUMBER(H38),J38+H38,NA()) -> 121 | AA38: =IF($AG38=1,$J38+$G38,NA()) -> 126 | AB38: =IF(AND($AG38=1,ISNUMBER($H38)),$J38+$H38,NA()) -> 121 | AC38: 37 | AG38: {=IFERROR(INDEX(Data!$AB$2:$AB$81,MATCH(A38,Data!$B$2:$B$81,0)),1)} -> 1
A39: API - Feature 38 | B39: API | C39: On Hold | D39: 45265 | E39: 45358 | G39: 93 | I39: 25 | J39: 336 | U39: =IF(AND(OR($S$1="All Product Lines",$S$1="",B39=$S$1),OR($T$1="All Statuses",$T$1="",C39=$T$1)),1,0) -> 1 | V39: =IF($AG39=1,$J39,NA()) -> 336 | W39: =IF($AG39=1,$G39,NA()) -> 93 | X39: =IF(AND($AG39=1,ISNUMBER($H39)),$H39,NA()) -> #N/A | Y39: =IF(ISNUMBER(G39),J39+G39,NA()) -> 429 | Z39: =IF(ISNUMBER(H39),J39+H39,NA()) -> #N/A | AA39: =IF($AG39=1,$J39+$G39,NA()) -> 429 | AB39: =IF(AND($AG39=1,ISNUMBER($H39)),$J39+$H39,NA()) -> #N/A | AC39: 38 | AG39: {=IFERROR(INDEX(Data!$AB$2:$AB$81,MATCH(A39,Data!$B$2:$B$81,0)),1)} -> 1
A40: Analytics Suite - Feature 39 | B40: Analytics Suite | C40: On Hold | D40: 45256 | E40: 45326 | G40: 70 | I40: 25 | J40: 327 | U40: =IF(AND(OR($S$1="All Product Lines",$S$1="",B40=$S$1),OR($T$1="All Statuses",$T$1="",C40=$T$1)),1,0) -> 1 | V40: =IF($AG40=1,$J40,NA()) -> 327 | W40: =IF($AG40=1,$G40,NA()) -> 70 | X40: =IF(AND($AG40=1,ISNUMBER($H40)),$H40,NA()) -> #N/A | Y40: =IF(ISNUMBER(G40),J40+G40,NA()) -> 397 | Z40: =IF(ISNUMBER(H40),J40+H40,NA()) -> #N/A | AA40: =IF($AG40=1,$J40+$G40,NA()) -> 397 | AB40: =IF(AND($AG40=1,ISNUMBER($H40)),$J40+$H40,NA()) -> #N/A | AC40: 39 | AG40: {=IFERROR(INDEX(Data!$AB$2:$AB$81,MATCH(A40,Data!$B$2:$B$81,0)),1)} -> 1
...

Sheet Budget
A1: Initiative ID | B1: Initiative Name | C1: Product Line | D1: Budget Allocated | E1: Budget Spent | F1: Variance ($) | G1: Variance (%) | H1: Include
